2018-02-12 11:58:58,019 ERROR manage.py [line:21]  28954 register agent fail!
2018-02-12 11:59:17,532 ERROR manage.py [line:21]  29298 register agent fail!
2018-02-12 11:59:50,840 ERROR manage.py [line:21]  29878 register agent fail!
Traceback (most recent call last):
  File "/home/dongxiaoyi/桌面/dbmonitor/src/agent/views/manage.py", line 19, in controller
    await performance.register()
  File "/home/dongxiaoyi/桌面/dbmonitor/src/agent/views/performance.py", line 341, in register
    await conn.close()
TypeError: object NoneType can't be used in 'await' expression
2018-02-12 12:01:46,862 ERROR manage.py [line:21]  30507 register agent fail!
Traceback (most recent call last):
  File "/home/dongxiaoyi/桌面/dbmonitor/src/agent/views/manage.py", line 19, in controller
    await performance.register()
  File "/home/dongxiaoyi/桌面/dbmonitor/src/agent/views/performance.py", line 341, in register
    await conn.close()
TypeError: object NoneType can't be used in 'await' expression
2018-02-12 12:02:18,489 ERROR manage.py [line:21]  31634 register agent fail!
Traceback (most recent call last):
  File "/home/dongxiaoyi/桌面/dbmonitor/src/agent/views/manage.py", line 19, in controller
    await performance.register()
  File "/home/dongxiaoyi/桌面/dbmonitor/src/agent/views/performance.py", line 318, in register
    print(server_pool)
NameError: name 'server_pool' is not defined
2018-02-12 12:02:29,345 ERROR manage.py [line:21]  31875 register agent fail!
Traceback (most recent call last):
  File "/home/dongxiaoyi/桌面/dbmonitor/src/agent/views/manage.py", line 19, in controller
    await performance.register()
  File "/home/dongxiaoyi/桌面/dbmonitor/src/agent/views/performance.py", line 342, in register
    await conn.close()
TypeError: object NoneType can't be used in 'await' expression
2018-02-12 12:05:13,679 ERROR manage.py [line:21]  418 register agent fail!
Traceback (most recent call last):
  File "/home/dongxiaoyi/桌面/dbmonitor/src/agent/views/manage.py", line 19, in controller
    await performance.register()
  File "/home/dongxiaoyi/桌面/dbmonitor/src/agent/views/performance.py", line 346, in register
    await conn.close()
TypeError: object NoneType can't be used in 'await' expression
2018-02-12 12:06:37,877 ERROR manage.py [line:21]  2293 register agent fail!
Traceback (most recent call last):
  File "/home/dongxiaoyi/桌面/dbmonitor/src/agent/views/manage.py", line 19, in controller
    await performance.register()
  File "/home/dongxiaoyi/桌面/dbmonitor/src/agent/views/performance.py", line 346, in register
    await conn.close()
TypeError: object NoneType can't be used in 'await' expression
2018-02-12 12:14:15,971 ERROR manage.py [line:29]  2952 save db information error!
Traceback (most recent call last):
  File "/home/dongxiaoyi/桌面/dbmonitor/src/agent/views/manage.py", line 27, in controller
    await performance.save_sql(new_server_pool)
  File "/home/dongxiaoyi/桌面/dbmonitor/src/agent/views/performance.py", line 260, in save_sql
    data = await self.dbinfo()
  File "/home/dongxiaoyi/桌面/dbmonitor/src/agent/views/performance.py", line 92, in dbinfo
    async with pool.acquire() as conn:
AttributeError: 'NoneType' object has no attribute 'acquire'
2018-02-12 12:17:38,246 ERROR manage.py [line:29]  4487 save db information error!
Traceback (most recent call last):
  File "/home/dongxiaoyi/桌面/dbmonitor/src/agent/views/manage.py", line 27, in controller
    await performance.save_sql(new_server_pool)
  File "/home/dongxiaoyi/桌面/dbmonitor/src/agent/views/performance.py", line 261, in save_sql
    data = await self.dbinfo()
  File "/home/dongxiaoyi/桌面/dbmonitor/src/agent/views/performance.py", line 93, in dbinfo
    async with pool.acquire() as conn:
AttributeError: 'NoneType' object has no attribute 'acquire'
2018-02-12 12:20:22,680 ERROR performance.py [line:264]  9340 Get agent data error
2018-02-12 12:21:22,194 ERROR performance.py [line:264]  10843 Get agent data error
Traceback (most recent call last):
  File "/home/dongxiaoyi/桌面/dbmonitor/src/agent/views/performance.py", line 262, in save_sql
    data = await self.dbinfo()
  File "/home/dongxiaoyi/桌面/dbmonitor/src/agent/views/performance.py", line 93, in dbinfo
    async with pool.acquire() as conn:
AttributeError: 'NoneType' object has no attribute 'acquire'
2018-02-12 12:22:06,772 ERROR performance.py [line:265]  11727 Get agent data error
Traceback (most recent call last):
  File "/home/dongxiaoyi/桌面/dbmonitor/src/agent/views/performance.py", line 263, in save_sql
    data = await self.dbinfo()
  File "/home/dongxiaoyi/桌面/dbmonitor/src/agent/views/performance.py", line 94, in dbinfo
    async with pool.acquire() as conn:
AttributeError: 'NoneType' object has no attribute 'acquire'
2018-02-12 12:23:11,596 ERROR performance.py [line:265]  11971 Get agent data error
Traceback (most recent call last):
  File "/home/dongxiaoyi/桌面/dbmonitor/src/agent/views/performance.py", line 263, in save_sql
    data = await self.dbinfo()
  File "/home/dongxiaoyi/桌面/dbmonitor/src/agent/views/performance.py", line 94, in dbinfo
    async with pool.acquire() as conn:
AttributeError: 'NoneType' object has no attribute 'acquire'
2018-02-12 12:28:23,594 ERROR performance.py [line:270]  17154 Get agent data error
Traceback (most recent call last):
  File "/home/dongxiaoyi/桌面/dbmonitor/src/agent/views/performance.py", line 268, in save_sql
    data = await self.dbinfo()
  File "/home/dongxiaoyi/桌面/dbmonitor/src/agent/views/performance.py", line 94, in dbinfo
    async with pool.acquire() as conn:
AttributeError: 'NoneType' object has no attribute 'acquire'
2018-02-12 16:55:28,610 ERROR manage.py [line:21]  11701 register agent fail!
Traceback (most recent call last):
  File "/home/dongxiaoyi/桌面/dbmonitor/src/agent/views/manage.py", line 19, in controller
    await performance.register()
  File "/home/dongxiaoyi/桌面/dbmonitor/src/agent/views/performance.py", line 335, in register
    host, = await cur.fetchall()
ValueError: not enough values to unpack (expected 1, got 0)
2018-02-12 16:55:59,011 ERROR manage.py [line:21]  11835 register agent fail!
Traceback (most recent call last):
  File "/home/dongxiaoyi/桌面/dbmonitor/src/agent/views/manage.py", line 19, in controller
    await performance.register()
  File "/home/dongxiaoyi/桌面/dbmonitor/src/agent/views/performance.py", line 335, in register
    host, = await cur.fetchall()
ValueError: not enough values to unpack (expected 1, got 0)
2018-02-12 16:59:11,017 ERROR manage.py [line:21]  16745 register agent fail!
Traceback (most recent call last):
  File "/home/dongxiaoyi/桌面/dbmonitor/src/agent/views/performance.py", line 336, in register
    (host, ) = await cur.fetchall()
ValueError: not enough values to unpack (expected 1, got 0)

During handling of the above exception, another exception occurred:

Traceback (most recent call last):
  File "/home/dongxiaoyi/桌面/dbmonitor/src/agent/views/manage.py", line 19, in controller
    await performance.register()
  File "/home/dongxiaoyi/桌面/dbmonitor/src/agent/views/performance.py", line 340, in register
    await cur.execute(register_sql)
  File "/home/dongxiaoyi/.pyenv/versions/3.6.2/lib/python3.6/site-packages/aiomysql/cursors.py", line 240, in execute
    yield from self._query(query)
  File "/home/dongxiaoyi/.pyenv/versions/3.6.2/lib/python3.6/site-packages/aiomysql/cursors.py", line 461, in _query
    yield from conn.query(q)
  File "/home/dongxiaoyi/.pyenv/versions/3.6.2/lib/python3.6/site-packages/aiomysql/connection.py", line 403, in query
    yield from self._read_query_result(unbuffered=unbuffered)
  File "/home/dongxiaoyi/.pyenv/versions/3.6.2/lib/python3.6/site-packages/aiomysql/connection.py", line 597, in _read_query_result
    yield from result.read()
  File "/home/dongxiaoyi/.pyenv/versions/3.6.2/lib/python3.6/site-packages/aiomysql/connection.py", line 850, in read
    first_packet = yield from self.connection._read_packet()
  File "/home/dongxiaoyi/.pyenv/versions/3.6.2/lib/python3.6/site-packages/aiomysql/connection.py", line 567, in _read_packet
    packet.check_error()
  File "/home/dongxiaoyi/.pyenv/versions/3.6.2/lib/python3.6/site-packages/pymysql/connections.py", line 393, in check_error
    err.raise_mysql_exception(self._data)
  File "/home/dongxiaoyi/.pyenv/versions/3.6.2/lib/python3.6/site-packages/pymysql/err.py", line 107, in raise_mysql_exception
    raise errorclass(errno, errval)
pymysql.err.InternalError: (1364, "Field 'dbs' doesn't have a default value")
2018-02-12 17:08:49,064 ERROR performance.py [line:329]  8346 (SQL syntax error: SELECT * FROM Agent;)
2018-02-12 17:09:48,799 ERROR performance.py [line:329]  9400 (SQL syntax error: SELECT * FROM Agent;)
Traceback (most recent call last):
  File "/home/dongxiaoyi/桌面/dbmonitor/src/agent/views/performance.py", line 327, in agent_dbs
    await cur.execute(dbs)
UnboundLocalError: local variable 'dbs' referenced before assignment
2018-02-12 17:17:46,834 ERROR performance.py [line:357]  27603 (SQL syntax error: INSERT INTO Agent(hostname, status, dbs) VALUES('127.0.0.1', 'running', '(('information_schema',), ('LearnSQL',), ('dbmonitor',), ('dbservice',), ('mxshop',), ('mysql',), ('performance_schema',), ('qqy',), ('restful',), ('restweb',), ('sys',), ('test',))');)
2018-02-12 17:18:35,924 ERROR performance.py [line:357]  28694 (SQL syntax error: INSERT INTO Agent(hostname, status, dbs) VALUES('127.0.0.1', 'running', '(('information_schema',), ('LearnSQL',), ('dbmonitor',), ('dbservice',), ('mxshop',), ('mysql',), ('performance_schema',), ('qqy',), ('restful',), ('restweb',), ('sys',), ('test',))');)
Traceback (most recent call last):
  File "/home/dongxiaoyi/桌面/dbmonitor/src/agent/views/performance.py", line 351, in register
    (host, ) = await cur.fetchall()
ValueError: not enough values to unpack (expected 1, got 0)

During handling of the above exception, another exception occurred:

Traceback (most recent call last):
  File "/home/dongxiaoyi/桌面/dbmonitor/src/agent/views/performance.py", line 355, in register
    await cur.execute(register_sql)
  File "/home/dongxiaoyi/.pyenv/versions/3.6.2/lib/python3.6/site-packages/aiomysql/cursors.py", line 240, in execute
    yield from self._query(query)
  File "/home/dongxiaoyi/.pyenv/versions/3.6.2/lib/python3.6/site-packages/aiomysql/cursors.py", line 461, in _query
    yield from conn.query(q)
  File "/home/dongxiaoyi/.pyenv/versions/3.6.2/lib/python3.6/site-packages/aiomysql/connection.py", line 403, in query
    yield from self._read_query_result(unbuffered=unbuffered)
  File "/home/dongxiaoyi/.pyenv/versions/3.6.2/lib/python3.6/site-packages/aiomysql/connection.py", line 597, in _read_query_result
    yield from result.read()
  File "/home/dongxiaoyi/.pyenv/versions/3.6.2/lib/python3.6/site-packages/aiomysql/connection.py", line 850, in read
    first_packet = yield from self.connection._read_packet()
  File "/home/dongxiaoyi/.pyenv/versions/3.6.2/lib/python3.6/site-packages/aiomysql/connection.py", line 567, in _read_packet
    packet.check_error()
  File "/home/dongxiaoyi/.pyenv/versions/3.6.2/lib/python3.6/site-packages/pymysql/connections.py", line 393, in check_error
    err.raise_mysql_exception(self._data)
  File "/home/dongxiaoyi/.pyenv/versions/3.6.2/lib/python3.6/site-packages/pymysql/err.py", line 107, in raise_mysql_exception
    raise errorclass(errno, errval)
pymysql.err.ProgrammingError: (1064, "You have an error in your SQL syntax; check the manual that corresponds to your MySQL server version for the right syntax to use near 'information_schema',), ('LearnSQL',), ('dbmonitor',), ('dbservice',), ('mxshop',' at line 1")
2018-02-12 17:19:00,758 ERROR performance.py [line:358]  29255 (SQL syntax error: INSERT INTO Agent(hostname, status, dbs) VALUES('127.0.0.1', 'running', '(('information_schema',), ('LearnSQL',), ('dbmonitor',), ('dbservice',), ('mxshop',), ('mysql',), ('performance_schema',), ('qqy',), ('restful',), ('restweb',), ('sys',), ('test',))');)
Traceback (most recent call last):
  File "/home/dongxiaoyi/桌面/dbmonitor/src/agent/views/performance.py", line 352, in register
    (host, ) = await cur.fetchall()
ValueError: not enough values to unpack (expected 1, got 0)

During handling of the above exception, another exception occurred:

Traceback (most recent call last):
  File "/home/dongxiaoyi/桌面/dbmonitor/src/agent/views/performance.py", line 356, in register
    await cur.execute(register_sql)
  File "/home/dongxiaoyi/.pyenv/versions/3.6.2/lib/python3.6/site-packages/aiomysql/cursors.py", line 240, in execute
    yield from self._query(query)
  File "/home/dongxiaoyi/.pyenv/versions/3.6.2/lib/python3.6/site-packages/aiomysql/cursors.py", line 461, in _query
    yield from conn.query(q)
  File "/home/dongxiaoyi/.pyenv/versions/3.6.2/lib/python3.6/site-packages/aiomysql/connection.py", line 403, in query
    yield from self._read_query_result(unbuffered=unbuffered)
  File "/home/dongxiaoyi/.pyenv/versions/3.6.2/lib/python3.6/site-packages/aiomysql/connection.py", line 597, in _read_query_result
    yield from result.read()
  File "/home/dongxiaoyi/.pyenv/versions/3.6.2/lib/python3.6/site-packages/aiomysql/connection.py", line 850, in read
    first_packet = yield from self.connection._read_packet()
  File "/home/dongxiaoyi/.pyenv/versions/3.6.2/lib/python3.6/site-packages/aiomysql/connection.py", line 567, in _read_packet
    packet.check_error()
  File "/home/dongxiaoyi/.pyenv/versions/3.6.2/lib/python3.6/site-packages/pymysql/connections.py", line 393, in check_error
    err.raise_mysql_exception(self._data)
  File "/home/dongxiaoyi/.pyenv/versions/3.6.2/lib/python3.6/site-packages/pymysql/err.py", line 107, in raise_mysql_exception
    raise errorclass(errno, errval)
pymysql.err.ProgrammingError: (1064, "You have an error in your SQL syntax; check the manual that corresponds to your MySQL server version for the right syntax to use near 'information_schema',), ('LearnSQL',), ('dbmonitor',), ('dbservice',), ('mxshop',' at line 1")
2018-02-12 17:20:02,497 ERROR manage.py [line:21]  31455 register agent fail!
Traceback (most recent call last):
  File "/home/dongxiaoyi/桌面/dbmonitor/src/agent/views/manage.py", line 19, in controller
    await performance.register()
  File "/home/dongxiaoyi/桌面/dbmonitor/src/agent/views/performance.py", line 339, in register
    dbs = await self.agent_dbs()
  File "/home/dongxiaoyi/桌面/dbmonitor/src/agent/views/performance.py", line 336, in agent_dbs
    return [db for list(db)[0] in dbs]
  File "/home/dongxiaoyi/桌面/dbmonitor/src/agent/views/performance.py", line 336, in <listcomp>
    return [db for list(db)[0] in dbs]
NameError: name 'db' is not defined
2018-02-12 17:20:25,844 ERROR performance.py [line:358]  32752 (SQL syntax error: INSERT INTO Agent(hostname, status, dbs) VALUES('127.0.0.1', 'running', '['information_schema', 'LearnSQL', 'dbmonitor', 'dbservice', 'mxshop', 'mysql', 'performance_schema', 'qqy', 'restful', 'restweb', 'sys', 'test']');)
Traceback (most recent call last):
  File "/home/dongxiaoyi/桌面/dbmonitor/src/agent/views/performance.py", line 352, in register
    (host, ) = await cur.fetchall()
ValueError: not enough values to unpack (expected 1, got 0)

During handling of the above exception, another exception occurred:

Traceback (most recent call last):
  File "/home/dongxiaoyi/桌面/dbmonitor/src/agent/views/performance.py", line 356, in register
    await cur.execute(register_sql)
  File "/home/dongxiaoyi/.pyenv/versions/3.6.2/lib/python3.6/site-packages/aiomysql/cursors.py", line 240, in execute
    yield from self._query(query)
  File "/home/dongxiaoyi/.pyenv/versions/3.6.2/lib/python3.6/site-packages/aiomysql/cursors.py", line 461, in _query
    yield from conn.query(q)
  File "/home/dongxiaoyi/.pyenv/versions/3.6.2/lib/python3.6/site-packages/aiomysql/connection.py", line 403, in query
    yield from self._read_query_result(unbuffered=unbuffered)
  File "/home/dongxiaoyi/.pyenv/versions/3.6.2/lib/python3.6/site-packages/aiomysql/connection.py", line 597, in _read_query_result
    yield from result.read()
  File "/home/dongxiaoyi/.pyenv/versions/3.6.2/lib/python3.6/site-packages/aiomysql/connection.py", line 850, in read
    first_packet = yield from self.connection._read_packet()
  File "/home/dongxiaoyi/.pyenv/versions/3.6.2/lib/python3.6/site-packages/aiomysql/connection.py", line 567, in _read_packet
    packet.check_error()
  File "/home/dongxiaoyi/.pyenv/versions/3.6.2/lib/python3.6/site-packages/pymysql/connections.py", line 393, in check_error
    err.raise_mysql_exception(self._data)
  File "/home/dongxiaoyi/.pyenv/versions/3.6.2/lib/python3.6/site-packages/pymysql/err.py", line 107, in raise_mysql_exception
    raise errorclass(errno, errval)
pymysql.err.ProgrammingError: (1064, "You have an error in your SQL syntax; check the manual that corresponds to your MySQL server version for the right syntax to use near 'information_schema', 'LearnSQL', 'dbmonitor', 'dbservice', 'mxshop', 'mysql', 'p' at line 1")
2018-02-12 17:21:01,088 ERROR performance.py [line:357]  1003 (SQL syntax error: INSERT INTO Agent(hostname, status, dbs) VALUES('127.0.0.1', 'running', '['information_schema', 'LearnSQL', 'dbmonitor', 'dbservice', 'mxshop', 'mysql', 'performance_schema', 'qqy', 'restful', 'restweb', 'sys', 'test']');)
Traceback (most recent call last):
  File "/home/dongxiaoyi/桌面/dbmonitor/src/agent/views/performance.py", line 351, in register
    (host, ) = await cur.fetchall()
ValueError: not enough values to unpack (expected 1, got 0)

During handling of the above exception, another exception occurred:

Traceback (most recent call last):
  File "/home/dongxiaoyi/桌面/dbmonitor/src/agent/views/performance.py", line 355, in register
    await cur.execute(register_sql)
  File "/home/dongxiaoyi/.pyenv/versions/3.6.2/lib/python3.6/site-packages/aiomysql/cursors.py", line 240, in execute
    yield from self._query(query)
  File "/home/dongxiaoyi/.pyenv/versions/3.6.2/lib/python3.6/site-packages/aiomysql/cursors.py", line 461, in _query
    yield from conn.query(q)
  File "/home/dongxiaoyi/.pyenv/versions/3.6.2/lib/python3.6/site-packages/aiomysql/connection.py", line 403, in query
    yield from self._read_query_result(unbuffered=unbuffered)
  File "/home/dongxiaoyi/.pyenv/versions/3.6.2/lib/python3.6/site-packages/aiomysql/connection.py", line 597, in _read_query_result
    yield from result.read()
  File "/home/dongxiaoyi/.pyenv/versions/3.6.2/lib/python3.6/site-packages/aiomysql/connection.py", line 850, in read
    first_packet = yield from self.connection._read_packet()
  File "/home/dongxiaoyi/.pyenv/versions/3.6.2/lib/python3.6/site-packages/aiomysql/connection.py", line 567, in _read_packet
    packet.check_error()
  File "/home/dongxiaoyi/.pyenv/versions/3.6.2/lib/python3.6/site-packages/pymysql/connections.py", line 393, in check_error
    err.raise_mysql_exception(self._data)
  File "/home/dongxiaoyi/.pyenv/versions/3.6.2/lib/python3.6/site-packages/pymysql/err.py", line 107, in raise_mysql_exception
    raise errorclass(errno, errval)
pymysql.err.ProgrammingError: (1064, "You have an error in your SQL syntax; check the manual that corresponds to your MySQL server version for the right syntax to use near 'information_schema', 'LearnSQL', 'dbmonitor', 'dbservice', 'mxshop', 'mysql', 'p' at line 1")
2018-02-12 17:21:43,402 ERROR performance.py [line:357]  3811 (SQL syntax error: INSERT INTO Agent(hostname, status, dbs) VALUES('127.0.0.1', 'running', '[['information_schema', 'LearnSQL', 'dbmonitor', 'dbservice', 'mxshop', 'mysql', 'performance_schema', 'qqy', 'restful', 'restweb', 'sys', 'test']]');)
Traceback (most recent call last):
  File "/home/dongxiaoyi/桌面/dbmonitor/src/agent/views/performance.py", line 351, in register
    (host, ) = await cur.fetchall()
ValueError: not enough values to unpack (expected 1, got 0)

During handling of the above exception, another exception occurred:

Traceback (most recent call last):
  File "/home/dongxiaoyi/桌面/dbmonitor/src/agent/views/performance.py", line 355, in register
    await cur.execute(register_sql)
  File "/home/dongxiaoyi/.pyenv/versions/3.6.2/lib/python3.6/site-packages/aiomysql/cursors.py", line 240, in execute
    yield from self._query(query)
  File "/home/dongxiaoyi/.pyenv/versions/3.6.2/lib/python3.6/site-packages/aiomysql/cursors.py", line 461, in _query
    yield from conn.query(q)
  File "/home/dongxiaoyi/.pyenv/versions/3.6.2/lib/python3.6/site-packages/aiomysql/connection.py", line 403, in query
    yield from self._read_query_result(unbuffered=unbuffered)
  File "/home/dongxiaoyi/.pyenv/versions/3.6.2/lib/python3.6/site-packages/aiomysql/connection.py", line 597, in _read_query_result
    yield from result.read()
  File "/home/dongxiaoyi/.pyenv/versions/3.6.2/lib/python3.6/site-packages/aiomysql/connection.py", line 850, in read
    first_packet = yield from self.connection._read_packet()
  File "/home/dongxiaoyi/.pyenv/versions/3.6.2/lib/python3.6/site-packages/aiomysql/connection.py", line 567, in _read_packet
    packet.check_error()
  File "/home/dongxiaoyi/.pyenv/versions/3.6.2/lib/python3.6/site-packages/pymysql/connections.py", line 393, in check_error
    err.raise_mysql_exception(self._data)
  File "/home/dongxiaoyi/.pyenv/versions/3.6.2/lib/python3.6/site-packages/pymysql/err.py", line 107, in raise_mysql_exception
    raise errorclass(errno, errval)
pymysql.err.ProgrammingError: (1064, "You have an error in your SQL syntax; check the manual that corresponds to your MySQL server version for the right syntax to use near 'information_schema', 'LearnSQL', 'dbmonitor', 'dbservice', 'mxshop', 'mysql', 'p' at line 1")
2018-02-12 17:21:59,676 ERROR performance.py [line:358]  5065 (SQL syntax error: INSERT INTO Agent(hostname, status, dbs) VALUES('127.0.0.1', 'running', '['information_schema', 'LearnSQL', 'dbmonitor', 'dbservice', 'mxshop', 'mysql', 'performance_schema', 'qqy', 'restful', 'restweb', 'sys', 'test']');)
Traceback (most recent call last):
  File "/home/dongxiaoyi/桌面/dbmonitor/src/agent/views/performance.py", line 352, in register
    (host, ) = await cur.fetchall()
ValueError: not enough values to unpack (expected 1, got 0)

During handling of the above exception, another exception occurred:

Traceback (most recent call last):
  File "/home/dongxiaoyi/桌面/dbmonitor/src/agent/views/performance.py", line 356, in register
    await cur.execute(register_sql)
  File "/home/dongxiaoyi/.pyenv/versions/3.6.2/lib/python3.6/site-packages/aiomysql/cursors.py", line 240, in execute
    yield from self._query(query)
  File "/home/dongxiaoyi/.pyenv/versions/3.6.2/lib/python3.6/site-packages/aiomysql/cursors.py", line 461, in _query
    yield from conn.query(q)
  File "/home/dongxiaoyi/.pyenv/versions/3.6.2/lib/python3.6/site-packages/aiomysql/connection.py", line 403, in query
    yield from self._read_query_result(unbuffered=unbuffered)
  File "/home/dongxiaoyi/.pyenv/versions/3.6.2/lib/python3.6/site-packages/aiomysql/connection.py", line 597, in _read_query_result
    yield from result.read()
  File "/home/dongxiaoyi/.pyenv/versions/3.6.2/lib/python3.6/site-packages/aiomysql/connection.py", line 850, in read
    first_packet = yield from self.connection._read_packet()
  File "/home/dongxiaoyi/.pyenv/versions/3.6.2/lib/python3.6/site-packages/aiomysql/connection.py", line 567, in _read_packet
    packet.check_error()
  File "/home/dongxiaoyi/.pyenv/versions/3.6.2/lib/python3.6/site-packages/pymysql/connections.py", line 393, in check_error
    err.raise_mysql_exception(self._data)
  File "/home/dongxiaoyi/.pyenv/versions/3.6.2/lib/python3.6/site-packages/pymysql/err.py", line 107, in raise_mysql_exception
    raise errorclass(errno, errval)
pymysql.err.ProgrammingError: (1064, "You have an error in your SQL syntax; check the manual that corresponds to your MySQL server version for the right syntax to use near 'information_schema', 'LearnSQL', 'dbmonitor', 'dbservice', 'mxshop', 'mysql', 'p' at line 1")
